[2022-03-29 15:25:46,956] {taskinstance.py:1037} INFO - Dependencies all met for <TaskInstance: python_operator_cine.create_csv manual__2022-03-29T20:25:35.310135+00:00 [queued]>
[2022-03-29 15:25:46,964] {taskinstance.py:1037} INFO - Dependencies all met for <TaskInstance: python_operator_cine.create_csv manual__2022-03-29T20:25:35.310135+00:00 [queued]>
[2022-03-29 15:25:46,965] {taskinstance.py:1243} INFO - 
--------------------------------------------------------------------------------
[2022-03-29 15:25:46,965] {taskinstance.py:1244} INFO - Starting attempt 1 of 1
[2022-03-29 15:25:46,965] {taskinstance.py:1245} INFO - 
--------------------------------------------------------------------------------
[2022-03-29 15:25:47,399] {taskinstance.py:1264} INFO - Executing <Task(PythonOperator): create_csv> on 2022-03-29 20:25:35.310135+00:00
[2022-03-29 15:25:47,402] {standard_task_runner.py:52} INFO - Started process 568 to run task
[2022-03-29 15:25:47,406] {standard_task_runner.py:76} INFO - Running: ['airflow', 'tasks', 'run', 'python_operator_cine', 'create_csv', 'manual__2022-03-29T20:25:35.310135+00:00', '--job-id', '200', '--raw', '--subdir', 'DAGS_FOLDER/ET_Univ_del_Cine_dags.py', '--cfg-path', '/tmp/tmp6xn8ve0z', '--error-file', '/tmp/tmpgd891149']
[2022-03-29 15:25:47,406] {standard_task_runner.py:77} INFO - Job 200: Subtask create_csv
[2022-03-29 15:25:47,751] {logging_mixin.py:109} INFO - Running <TaskInstance: python_operator_cine.create_csv manual__2022-03-29T20:25:35.310135+00:00 [running]> on host LAPTOP-5HJG55H7.localdomain
[2022-03-29 15:25:48,563] {taskinstance.py:1429} INFO - Exporting the following env vars:
AIRFLOW_CTX_DAG_OWNER=airflow
AIRFLOW_CTX_DAG_ID=python_operator_cine
AIRFLOW_CTX_TASK_ID=create_csv
AIRFLOW_CTX_EXECUTION_DATE=2022-03-29T20:25:35.310135+00:00
AIRFLOW_CTX_DAG_RUN_ID=manual__2022-03-29T20:25:35.310135+00:00
[2022-03-29 15:25:48,579] {base.py:70} INFO - Using connection to: id: airflow-universities. Host: training-main.cghe7e6sfljt.us-east-1.rds.amazonaws.com, Port: 5432, Schema: training, Login: alkymer, Password: ***, extra: {}
[2022-03-29 15:25:50,179] {taskinstance.py:1718} ERROR - Task failed with exception
Traceback (most recent call last):
  File "/home/lowenhard/acceleration/env/lib/python3.8/site-packages/airflow/models/taskinstance.py", line 1334, in _run_raw_task
    self._execute_task_with_callbacks(context)
  File "/home/lowenhard/acceleration/env/lib/python3.8/site-packages/airflow/models/taskinstance.py", line 1460, in _execute_task_with_callbacks
    result = self._execute_task(context, self.task)
  File "/home/lowenhard/acceleration/env/lib/python3.8/site-packages/airflow/models/taskinstance.py", line 1516, in _execute_task
    result = execute_callable(context=context)
  File "/home/lowenhard/acceleration/env/lib/python3.8/site-packages/airflow/operators/python.py", line 174, in execute
    return_value = self.execute_callable()
  File "/home/lowenhard/acceleration/env/lib/python3.8/site-packages/airflow/operators/python.py", line 188, in execute_callable
    return self.python_callable(*self.op_args, **self.op_kwargs)
  File "/home/lowenhard/airflow/dags/ET_Univ_del_Cine_dags.py", line 36, in get_data_cine
    df.to_csv(os.path.join(parent_folder, 'files/ET_Univ_del_Cine.csv', header=header, index=False))
TypeError: join() got an unexpected keyword argument 'header'
[2022-03-29 15:25:51,940] {taskinstance.py:1272} INFO - Marking task as FAILED. dag_id=python_operator_cine, task_id=create_csv, execution_date=20220329T202535, start_date=20220329T202546, end_date=20220329T202551
[2022-03-29 15:25:52,309] {standard_task_runner.py:89} ERROR - Failed to execute job 200 for task create_csv
Traceback (most recent call last):
  File "/home/lowenhard/acceleration/env/lib/python3.8/site-packages/airflow/task/task_runner/standard_task_runner.py", line 85, in _start_by_fork
    args.func(args, dag=self.dag)
  File "/home/lowenhard/acceleration/env/lib/python3.8/site-packages/airflow/cli/cli_parser.py", line 48, in command
    return func(*args, **kwargs)
  File "/home/lowenhard/acceleration/env/lib/python3.8/site-packages/airflow/utils/cli.py", line 92, in wrapper
    return f(*args, **kwargs)
  File "/home/lowenhard/acceleration/env/lib/python3.8/site-packages/airflow/cli/commands/task_command.py", line 298, in task_run
    _run_task_by_selected_method(args, dag, ti)
  File "/home/lowenhard/acceleration/env/lib/python3.8/site-packages/airflow/cli/commands/task_command.py", line 107, in _run_task_by_selected_method
    _run_raw_task(args, ti)
  File "/home/lowenhard/acceleration/env/lib/python3.8/site-packages/airflow/cli/commands/task_command.py", line 180, in _run_raw_task
    ti._run_raw_task(
  File "/home/lowenhard/acceleration/env/lib/python3.8/site-packages/airflow/utils/session.py", line 70, in wrapper
    return func(*args, session=session, **kwargs)
  File "/home/lowenhard/acceleration/env/lib/python3.8/site-packages/airflow/models/taskinstance.py", line 1334, in _run_raw_task
    self._execute_task_with_callbacks(context)
  File "/home/lowenhard/acceleration/env/lib/python3.8/site-packages/airflow/models/taskinstance.py", line 1460, in _execute_task_with_callbacks
    result = self._execute_task(context, self.task)
  File "/home/lowenhard/acceleration/env/lib/python3.8/site-packages/airflow/models/taskinstance.py", line 1516, in _execute_task
    result = execute_callable(context=context)
  File "/home/lowenhard/acceleration/env/lib/python3.8/site-packages/airflow/operators/python.py", line 174, in execute
    return_value = self.execute_callable()
  File "/home/lowenhard/acceleration/env/lib/python3.8/site-packages/airflow/operators/python.py", line 188, in execute_callable
    return self.python_callable(*self.op_args, **self.op_kwargs)
  File "/home/lowenhard/airflow/dags/ET_Univ_del_Cine_dags.py", line 36, in get_data_cine
    df.to_csv(os.path.join(parent_folder, 'files/ET_Univ_del_Cine.csv', header=header, index=False))
TypeError: join() got an unexpected keyword argument 'header'
[2022-03-29 15:25:52,427] {local_task_job.py:211} WARNING - State of this instance has been externally set to failed. Terminating instance.
[2022-03-29 15:25:52,430] {process_utils.py:120} INFO - Sending Signals.SIGTERM to group 568. PIDs of all processes in the group: [568]
[2022-03-29 15:25:52,430] {process_utils.py:75} INFO - Sending the signal Signals.SIGTERM to group 568
[2022-03-29 15:25:52,430] {process_utils.py:70} INFO - Process psutil.Process(pid=568, status='terminated', exitcode=1, started='15:25:46') (568) terminated with exit code 1
